[2017/04/07 09:46:09] :: [pool-1-thread-20] :: Base path for the test = C:\New Selenium\Salesforce_QA_Automation\ADT_Resources\<br><br>[2017/04/07 09:46:09] :: [pool-1-thread-20] :: Current Thread Name for the test is "pool-1-thread-20"<br><br>[2017/04/07 09:46:23] :: [pool-1-thread-20] :: The user has launched 'http://test.salesforce.com<br><br>[2017/04/07 09:46:24] :: [pool-1-thread-20] :: The user has creating SalesCancelINVorder<br><br>[2017/04/07 09:46:41] :: [pool-1-thread-20] :: arindom.das@move.com.qa has successfully loggedin<br><br>[2017/04/07 09:46:44] :: [pool-1-thread-20] :: Successfully navigated to Home page<br><br>[2017/04/07 09:46:45] :: [pool-1-thread-20] :: File path is = C:\New Selenium\Salesforce_QA_Automation\ADT_Resources\ .<br><br>[2017/04/07 09:49:31] :: [pool-1-thread-20] :: Exception occurred. null<br><br>[2017/04/07 09:49:36] :: [pool-1-thread-20] :: Closing the Browser Instance<br><br>[2017/04/07 09:49:36] :: [pool-1-thread-20] ::  File Name: Assert.java Method name: fail(91)<br> File Name: Assert.java Method name: assertTrue(43)<br> File Name: Assert.java Method name: assertTrue(54)<br> File Name: Common.java Method name: loginUserNameAccountID(811)<br> File Name: C:/New Selenium/Salesforce_QA_Automation/ADT_Resources/SalesForce/FeatureFiles/AMENDMENT/New_Sales_Cancel_Inventory_Connections(SM)for_Seller_Bundle _DL.feature Method name: When I login with "Emily Morrison" and launch "1"(9)<br><br>Complete Error Message: <br><br><br>