[2018/01/19 15:00:27] :: [pool-1-thread-6] :: Base path for the test = C:\New Selenium\Salesforce_QA_Automation\ADT_Resources\<br><br>[2018/01/19 15:00:27] :: [pool-1-thread-6] :: Current Thread Name for the test is "pool-1-thread-6"<br><br>[2018/01/19 15:00:36] :: [pool-1-thread-6] :: The user has launched 'https://qainc--qa.cs30.my.salesforce.com<br><br>[2018/01/19 15:00:37] :: [pool-1-thread-6] :: The user has creating SalesCancel_NonInvorder<br><br>[2018/01/19 15:00:50] :: [pool-1-thread-6] :: arindom.das@move.com.qa has successfully loggedin<br><br>[2018/01/19 15:00:52] :: [pool-1-thread-6] :: Successfully navigated to Home page<br><br>[2018/01/19 15:00:53] :: [pool-1-thread-6] :: File path is = C:\New Selenium\Salesforce_QA_Automation\ADT_Resources\ .<br><br>[2018/01/19 15:00:56] :: [pool-1-thread-6] :: Exception occurred. 3<br><br>[2018/01/19 15:01:03] :: [pool-1-thread-6] :: Closing the Browser Instance<br><br>[2018/01/19 15:01:04] :: [pool-1-thread-6] ::  File Name: Assert.java Method name: fail(86)<br> File Name: Assert.java Method name: assertTrue(41)<br> File Name: Assert.java Method name: assertTrue(52)<br> File Name: sfdc.java Method name: loginUserNameAccountID(395)<br> File Name: C:/New Selenium/Salesforce_QA_Automation/ADT_Resources/SalesForce/FeatureFiles/Cancel/New_Sales_Cancel_TopProducerCRM_NonInventory_With_Credit_Amount_DL.feature Method name: When I am entering "Emily Morrison" and launch "17"(9)<br><br>Complete Error Message: null<br><br><br>