[2017/12/04 15:52:52] :: [pool-1-thread-6] :: Base path for the test = C:\New Selenium\Salesforce_QA_Automation\ADT_Resources\<br><br>[2017/12/04 15:52:52] :: [pool-1-thread-6] :: Current Thread Name for the test is "pool-1-thread-6"<br><br>[2017/12/04 15:53:02] :: [pool-1-thread-6] :: The user has launched 'https://qainc--qa.cs30.my.salesforce.com<br><br>[2017/12/04 15:53:03] :: [pool-1-thread-6] :: The user has creating Collection_Commissionorder<br><br>[2017/12/04 15:53:18] :: [pool-1-thread-6] :: arindom.das@move.com.qa has successfully loggedin<br><br>[2017/12/04 15:53:19] :: [pool-1-thread-6] :: Successfully navigated to Home page<br><br>[2017/12/04 15:53:20] :: [pool-1-thread-6] :: File path is = C:\New Selenium\Salesforce_QA_Automation\ADT_Resources\ .<br><br>[2017/12/04 15:54:26] :: [pool-1-thread-6] :: Exception occurred. null<br><br>[2017/12/04 15:54:33] :: [pool-1-thread-6] :: Closing the Browser Instance<br><br>[2017/12/04 15:54:33] :: [pool-1-thread-6] ::  File Name: Assert.java Method name: fail(86)<br> File Name: Assert.java Method name: assertTrue(41)<br> File Name: Assert.java Method name: assertTrue(52)<br> File Name: Common.java Method name: loginUserNameAccountID(782)<br> File Name: C:/New Selenium/Salesforce_QA_Automation/ADT_Resources/SalesForce/FeatureFiles/COLLECTION_COMMISSIONS/Collection_Commission_Mansoor_Ghatila3.feature Method name: When I login with "Mansoor Ghatila" and launch "1"(9)<br><br>Complete Error Message: null<br><br><br>